Workbook

Sheet Reson Not Switched
A1: Conversion_Status | B1: Lost
A3: Row Labels | B3: Count of Lead_ID
A4: Imprest fees not refundable | B4: 1
A5: No 0% EMI awareness | B5: 1
A6: Other | B6: 1
A7: No after-school program (Beyond the Bell) | B7: 1
A8: No counselling program (SOCH) | B8: 3
A9: Fees too high – unaware of discounts | B9: 3
A10: Transport not available | B10: 3
A11: Safety concerns (anti-ragging, POCSO) | B11: 3
A12: No robotics/coding lab interest | B12: 4
A13: Curriculum mismatch | B13: 4
A14: No sibling discount | B14: 4
A15: Happy with current school | B15: 5
... A19: Grand Total | B19: 48

Sheet Raw_Data
A1: Lead_ID | B1: Parent_Type | C1: Current_School | D1: Child_Grade | E1: Call_Date | F1: Call_Outcome | G1: Reason_Not_Switched | H1: Conversion_Status | I1: Followup_Needed | J1: Transport_Feasibility | K1: Safety_Mentioned | L1: SeatBlocking_NonRefundable | M1: Tuition_Installments | N1: 0Percent_EMI | O1: OneShot_Discount | P1: Sibling_Concession | Q1: Corporate_TieUp | R1: MidYear_Concession | S1: Imprest_Refundable | T1: Internal_Transfer_125Branches | U1: SOCH_Counselling | V1: Beyond_The_Bell | W1: Robotics_Lab | X1: Coding_Lab | Y1: Dance_Music_Theatre | Z1: Active_Schooling | AA1: OCFP_Program | AB1: SeatBlocking_Objection | AC1: Imprest_Fees_Concern | AD1: Transport_Not_Available | AE1: Safety_Concern | AF1: Workshop_Interest | AG1: Followup_Priority
A2: LD001 | B2: Transfer (Already in other school) | C2: DPS | D2: Grade 2 | E2: 2026-04-16 | F2: Interested | G2: No after-school program (Beyond the Bell) | H2: Enrolled | I2: No | J2: No - not available | K2: No | L2: Yes | M2: Yes | N2: No | O2: No | P2: No | Q2: No | R2: No | S2: No | T2: No | U2: No | V2: No | W2: No | X2: Yes | Y2: No | Z2: No | AA2: No | AB2: No | AC2: Yes | AD2: Yes | AE2: No | AF2: Yes | AG2: N/A
A3: LD002 | B3: Kindergarten (New) | C3: N/A | D3: Grade 2 | E3: 2026-05-22 | F3: Interested | G3: Safety concerns (anti-ragging, POCSO) | H3: Lost | I3: No | J3: Yes - within route | K3: No | L3: No | M3: No | N3: No | O3: No | P3: No | Q3: Yes | R3: No | S3: No | T3: Yes | U3: No | V3: Yes | W3: No | X3: No | Y3: No | Z3: No | AA3: No | AB3: Yes | AC3: No | AD3: No | AE3: No | AF3: No | AG3: N/A
A4: LD003 | B4: Kindergarten (New) | C4: N/A | D4: Grade 1 | E4: 2026-04-11 | F4: Not interested | G4: Imprest fees not refundable | H4: Follow-up pending | I4: Yes | J4: No - not available | K4: No | L4: No | M4: No | N4: No | O4: Yes | P4: Yes | Q4: No | R4: No | S4: No | T4: No | U4: No | V4: No | W4: No | X4: No | Y4: No | Z4: No | AA4: No | AB4: Yes | AC4: No | AD4: Yes | AE4: Yes | AF4: No | AG4: Low
A5: LD004 | B5: Transfer (Already in other school) | C5: St. Mary's | D5: Grade 3 | E5: 2026-04-15 | F5: Callback requested | G5: No sibling discount | H5: Lost | I5: Yes | J5: Yes - within route | K5: Yes | L5: No | M5: No | N5: No | O5: Yes | P5: No | Q5: No | R5: No | S5: No | T5: No | U5: Yes | V5: No | W5: No | X5: No | Y5: Yes | Z5: No | AA5: No | AB5: No | AC5: No | AD5: No | AE5: No | AF5: No | AG5: N/A
A6: LD005 | B6: Kindergarten (New) | C6: N/A | D6: Grade 6 | E6: 2026-05-19 | F6: Interested | G6: Other | H6: Enrolled | I6: No | J6: Not sure | K6: No | L6: Yes | M6: No | N6: Yes | O6: No | P6: No | Q6: No | R6: No | S6: No | T6: Yes | U6: No | V6: No | W6: No | X6: No | Y6: Yes | Z6: No | AA6: Yes | AB6: No | AC6: No | AD6: No | AE6: No | AF6: Yes | AG6: N/A
A7: LD006 | B7: Transfer (Already in other school) | C7: Jain International | D7: UKG | E7: 2026-04-17 | F7: Not interested | G7: Curriculum mismatch | H7: Lost | I7: Yes | J7: No - not available | K7: No | L7: Yes | M7: No | N7: No | O7: No | P7: No | Q7: No | R7: Yes | S7: No | T7: No | U7: No | V7: No | W7: Yes | X7: Yes | Y7: No | Z7: No | AA7: No | AB7: No | AC7: Yes | AD7: Yes | AE7: Yes | AF7: No | AG7: N/A
A8: LD007 | B8: Kindergarten (New) | C8: N/A | D8: UKG | E8: 2026-05-17 | F8: Callback requested | G8: Curriculum mismatch | H8: Lost | I8: Yes | J8: No - not available | K8: No | L8: Yes | M8: No | N8: No | O8: No | P8: No | Q8: Yes | R8: No | S8: No | T8: Yes | U8: No | V8: No | W8: Yes | X8: Yes | Y8: No | Z8: Yes | AA8: No | AB8: Yes | AC8: No | AD8: Yes | AE8: Yes | AF8: No | AG8: N/A
A9: LD008 | B9: Transfer (Already in other school) | C9: DPS | D9: Nursery | E9: 2026-05-12 | F9: Callback requested | G9: Happy with current school | H9: Enrolled | I9: Yes | J9: No - not available | K9: Yes | L9: No | M9: No | N9: No | O9: No | P9: Yes | Q9: Yes | R9: No | S9: No | T9: No | U9: No | V9: No | W9: No | X9: No | Y9: No | Z9: No | AA9: No | AB9: Yes | AC9: Yes | AD9: Yes | AE9: No | AF9: Yes | AG9: N/A
A10: LD009 | B10: Kindergarten (New) | C10: N/A | D10: Nursery | E10: 2026-05-08 | F10: Not interested | G10: Other | H10: Follow-up pending | I10: Yes | J10: Yes - within route | K10: No | L10: Yes | M10: Yes | N10: No | O10: No | P10: Yes | Q10: Yes | R10: No | S10: No | T10: No | U10: No | V10: No | W10: No | X10: No | Y10: No | Z10: No | AA10: No | AB10: Yes | AC10: Yes | AD10: No | AE10: No | AF10: Yes | AG10: Low
A11: LD010 | B11: Kindergarten (New) | C11: N/A | D11: LKG | E11: 2026-04-01 | F11: Not interested | G11: Curriculum mismatch | H11: Follow-up pending | I11: Yes | J11: Yes - within route | K11: Yes | L11: Yes | M11: No | N11: No | O11: No | P11: No | Q11: No | R11: No | S11: No | T11: No | U11: No | V11: No | W11: Yes | X11: No | Y11: Yes | Z11: No | AA11: No | AB11: Yes | AC11: Yes | AD11: No | AE11: Yes | AF11: No | AG11: Low
A12: LD011 | B12: Kindergarten (New) | C12: N/A | D12: Grade 7 | E12: 2026-04-14 | F12: Callback requested | G12: No corporate tie-up | H12: Lost | I12: No | J12: No - not available | K12: Yes | L12: No | M12: Yes | N12: No | O12: No | P12: Yes | Q12: No | R12: Yes | S12: No | T12: Yes | U12: No | V12: No | W12: No | X12: Yes | Y12: No | Z12: No | AA12: No | AB12: Yes | AC12: Yes | AD12: Yes | AE12: No | AF12: Yes | AG12: N/A
... A101: LD100 | B101: Kindergarten (New) | C101: N/A | D101: Nursery | E101: 2026-05-29 | F101: Interested | G101: Happy with current school | H101: Lost | I101: No | J101: Yes - within route | K101: No | L101: Yes | M101: Yes | N101: Yes | O101: No | P101: Yes | Q101: No | R101: No | S101: No | T101: No | U101: No | V101: No | W101: No | X101: No | Y101: No | Z101: No | AA101: No | AB101: Yes | AC101: Yes | AD101: No | AE101: No | AF101: No | AG101: N/A

Sheet Dashboard
A1: ORCHIDS INTERNATIONAL SCHOOL – PARENT LEAD ANALYSIS DASHBOARD | I1: ORCHIDS INTERNATIONAL SCHOOL – PARENT LEAD ANALYSIS DASHBOARD | Q1: ORCHIDS INTERNATIONAL SCHOOL – PARENT LEAD ANALYSIS DASHBOARD
A2: Campaign Period: 01-Apr-2026 to 30-May-2026 | Data as of: 30-May-2026
A4: 📊 KEY METRICS | F4: AWARENESS GAP (% of leads who were AWARE)
A5: Total Leads Called | B5: =COUNTA(Raw_Data!A2:A101) -> 100 | F5: Feature / Initiative | G5: # Aware | H5: % Aware
A6: Enrolled | B6: =COUNTIF(Raw_Data!H2:H101,"Enrolled") -> 18 | F6: SeatBlocking_NonRefundable | G6: =COUNTIF(Raw_Data!L2:L101,"Yes") -> 31 | H6: =IFERROR(G6/B5,0) -> 0.31
A7: Lost | B7: =COUNTIF(Raw_Data!H2:H101,"Lost") -> 48 | F7: Tuition_Installments | G7: =COUNTIF(Raw_Data!M2:M101,"Yes") -> 25 | H7: =IFERROR(G7/B5,0) -> 0.25
A8: Follow-up Pending | B8: =COUNTIF(Raw_Data!H2:H101,"Follow-up pending") -> 34 | F8: 0Percent_EMI | G8: =COUNTIF(Raw_Data!N2:N101,"Yes") -> 20 | H8: =IFERROR(G8/B5,0) -> 0.2
A9: Conversion Rate | B9: =IFERROR(B6/B5,0) -> 0.18 | F9: OneShot_Discount | G9: =COUNTIF(Raw_Data!O2:O101,"Yes") -> 27 | H9: =IFERROR(G9/B5,0) -> 0.27
A10: Avg Awareness per Lead | B10: =IFERROR(COUNTIF(Raw_Data!L2:AA101,"Yes")/(COUNTA(Raw_Data!A2:A101)*16),0) -> 0.21125 | F10: Sibling_Concession | G10: =COUNTIF(Raw_Data!P2:P101,"Yes") -> 33 | H10: =IFERROR(G10/B5,0) -> 0.33
F11: Corporate_TieUp | G11: =COUNTIF(Raw_Data!Q2:Q101,"Yes") -> 18 | H11: =IFERROR(G11/B5,0) -> 0.18
F12: MidYear_Concession | G12: =COUNTIF(Raw_Data!R2:R101,"Yes") -> 18 | H12: =IFERROR(G12/B5,0) -> 0.18
A13: 🔽 CONVERSION FUNNEL | F13: Imprest_Refundable | G13: =COUNTIF(Raw_Data!S2:S101,"Yes") -> 11 | H13: =IFERROR(G13/B5,0) -> 0.11
A14: Stage | B14: Count | C14: % of Total | F14: Internal_Transfer_125Branches | G14: =COUNTIF(Raw_Data!T2:T101,"Yes") -> 22 | H14: =IFERROR(G14/B5,0) -> 0.22
A15: Total Calls Made | B15: =B5 -> 100 | C15: =IFERROR(C15/B15,0) -> 0 | F15: SOCH_Counselling | G15: =COUNTIF(Raw_Data!U2:U101,"Yes") -> 13 | H15: =IFERROR(G15/B5,0) -> 0.13
A16: Interested / CB | B16: =COUNTIF(Raw_Data!F2:F101,"Interested")+COUNTIF(Raw_Data!F2:F101,"Callback requested") -> 70 | C16: =IFERROR(C16/B15,0) -> 0 | F16: Beyond_The_Bell | G16: =COUNTIF(Raw_Data!V2:V101,"Yes") -> 8 | H16: =IFERROR(G16/B5,0) -> 0.08
A17: Follow-up Pending | B17: =B8 -> 34 | C17: =IFERROR(C17/B15,0) -> 0 | F17: Robotics_Lab | G17: =COUNTIF(Raw_Data!W2:W101,"Yes") -> 28 | H17: =IFERROR(G17/B5,0) -> 0.28
A18: Enrolled | B18: =B6 -> 18 | C18: =IFERROR(C18/B15,0) -> 0 | F18: Coding_Lab | G18: =COUNTIF(Raw_Data!X2:X101,"Yes") -> 23 | H18: =IFERROR(G18/B5,0) -> 0.23
F19: Dance_Music_Theatre | G19: =COUNTIF(Raw_Data!Y2:Y101,"Yes") -> 34 | H19: =IFERROR(G19/B5,0) -> 0.34
A20: ⚡ FOLLOW-UP PRIORITY SUMMARY | F20: Active_Schooling | G20: =COUNTIF(Raw_Data!Z2:Z101,"Yes") -> 20 | H20: =IFERROR(G20/B5,0) -> 0.2
A21: Priority Level | B21: Count | C21: % of Follow-ups | F21: OCFP_Program | G21: =COUNTIF(Raw_Data!AA2:AA101,"Yes") -> 7 | H21: =IFERROR(G21/B5,0) -> 0.07
A22: High | B22: =COUNTIF(Raw_Data!AG2:AG101,"High") -> 13 | C22: =IFERROR(B22/B8,0) -> 0.38235294 | F22: Note: Cells with % < 20% indicate critical awareness gaps – prioritise in training.
A23: Medium | B23: =COUNTIF(Raw_Data!AG2:AG101,"Medium") -> 1 | C23: =IFERROR(B23/B8,0) -> 0.029411765
A24: Low | B24: =COUNTIF(Raw_Data!AG2:AG101,"Low") -> 20 | C24: =IFERROR(B24/B8,0) -> 0.58823529 | F24: TOP REASONS FOR NON-ENROLLMENT (use PivotTable to sort)
A25: N/A | B25: =COUNTIF(Raw_Data!AG2:AG101,"N/A") -> 66 | C25: =IFERROR(B25/B8,0) -> 1.9411765 | F25: Reason_Not_Switched | G25: Count | H25: % of Lost
F26: Seat blocking non-refundable too high | G26: =COUNTIFS(Raw_Data!G2:G101,F26,Raw_Data!H2:H101,"Lost") -> 5 | H26: =IFERROR(G26/B7,0) -> 0.10416667
F27: No 0% EMI awareness | G27: =COUNTIFS(Raw_Data!G2:G101,F27,Raw_Data!H2:H101,"Lost") -> 1 | H27: =IFERROR(G27/B7,0) -> 0.020833333
F28: No sibling discount | G28: =COUNTIFS(Raw_Data!G2:G101,F28,Raw_Data!H2:H101,"Lost") -> 4 | H28: =IFERROR(G28/B7,0) -> 0.083333333
F29: No corporate tie-up | G29: =COUNTIFS(Raw_Data!G2:G101,F29,Raw_Data!H2:H101,"Lost") -> 5 | H29: =IFERROR(G29/B7,0) -> 0.10416667
A30: TRANSPORT FEASIBILITY BREAKDOWN | F30: Imprest fees not refundable | G30: =COUNTIFS(Raw_Data!G2:G101,F30,Raw_Data!H2:H101,"Lost") -> 1 | H30: =IFERROR(G30/B7,0) -> 0.020833333
A31: Transport Status | B31: Count | C31: % of Total | F31: Transport not available | G31: =COUNTIFS(Raw_Data!G2:G101,F31,Raw_Data!H2:H101,"Lost") -> 3 | H31: =IFERROR(G31/B7,0) -> 0.0625
A32: Yes - within route | B32: =COUNTIF(Raw_Data!J2:J101,"Yes - within route") -> 37 | C32: =IFERROR(B32/B5,0) -> 0.37 | F32: No knowledge of 125+ branch transfer | G32: =COUNTIFS(Raw_Data!G2:G101,F32,Raw_Data!H2:H101,"Lost") -> 5 | H32: =IFERROR(G32/B7,0) -> 0.10416667
A33: No - not available | B33: =COUNTIF(Raw_Data!J2:J101,"No - not available") -> 47 | C33: =IFERROR(B33/B5,0) -> 0.47 | F33: Safety concerns (anti-ragging, POCSO) | G33: =COUNTIFS(Raw_Data!G2:G101,F33,Raw_Data!H2:H101,"Lost") -> 3 | H33: =IFERROR(G33/B7,0) -> 0.0625
A34: Not sure | B34: =COUNTIF(Raw_Data!J2:J101,"Not sure") -> 16 | C34: =IFERROR(B34/B5,0) -> 0.16 | F34: No counselling program (SOCH) | G34: =COUNTIFS(Raw_Data!G2:G101,F34,Raw_Data!H2:H101,"Lost") -> 3 | H34: =IFERROR(G34/B7,0) -> 0.0625
F35: Curriculum mismatch | G35: =COUNTIFS(Raw_Data!G2:G101,F35,Raw_Data!H2:H101,"Lost") -> 4 | H35: =IFERROR(G35/B7,0) -> 0.083333333
F36: Fees too high – unaware of discounts | G36: =COUNTIFS(Raw_Data!G2:G101,F36,Raw_Data!H2:H101,"Lost") -> 3 | H36: =IFERROR(G36/B7,0) -> 0.0625
A37: FOLLOW-UP LIST – How to view high-priority leads:
A38: 1. Go to Raw_Data sheet.
A39: 2. Click any cell in row 1 > Data > Filter (if not already on).
A40: 3. Click the Followup_Priority column dropdown > select 'High'.
A41: 4. Additionally filter Followup_Needed = 'Yes' to narrow results.
...
